Workbook

Sheet Summary
A1: Influencer Intelligence Platforms — HypeAuditor vs Viral Pitch vs CultureX
A2: Prepared for Dentsu Influence Indonesia, 30 Sep 2026. All prices in USD, excluding tax. Figures link to the Pricing, Requirements and Limitations tabs.
B4: HypeAuditor | C4: Viral Pitch | D4: CultureX
A5: Role in evaluation | B5: Incumbent (responded to 12 feedback items) | C5: Challenger (proposal, Sep 2026) | D5: Challenger (Enterprise UNLIMITED plan)
A6: Base licence, 12-month Indonesia (annual) | B6: =Pricing!J7 -> 55000 | C6: =Pricing!F7 -> 35988 | D6: =Pricing!I7 -> 54000
A7: Year-1 cost incl. TikTok competitor analysis | B7: =Pricing!D27 -> 205000 | C7: =Pricing!E27 -> 35988 | D7: =Pricing!F27 -> 54000
A8: Year-1 cost vs Viral Pitch | B8: =Pricing!D28 -> 5.6963432 | C8: =Pricing!E28 -> 1 | D8: =Pricing!F28 -> 1.5005002
A9: RFP options priced | B9: Baseline only ($55k / yr) | C9: 1 of 6 | D9: 6 of 6
A10: Requirements met / partial (of 12) | B10: ='Dentsu Requirements Fit'!C20&" met / "&'Dentsu Requirements Fit'!C21&" partial" -> 1 met / 6 partial | C10: ='Dentsu Requirements Fit'!E20&" met / "&'Dentsu Requirements Fit'!E21&" partial" -> 5 met / 6 partial | D10: ='Dentsu Requirements Fit'!G20&" met / "&'Dentsu Requirements Fit'!G21&" partial" -> 3 met / 4 partial
A11: Capacity checks 'Not enough' (of 12) | B11: ='Limitations & Enterprise Fit'!D70 -> 2 | C11: ='Limitations & Enterprise Fit'!G70 -> 3 | D11: ='Limitations & Enterprise Fit'!J70 -> 7
A12: High-severity limitations | B12: ='Limitations & Enterprise Fit'!D72 -> 4 | C12: ='Limitations & Enterprise Fit'!G72 -> 2 | D12: ='Limitations & Enterprise Fit'!J72 -> 7
A13: Enterprise-level verdict | B13: ='Limitations & Enterprise Fit'!D74 -> NOT ENOUGH for enterprise as quoted | C13: ='Limitations & Enterprise Fit'!G74 -> Enterprise-capable with conditions | D13: ='Limitations & Enterprise Fit'!J74 -> NOT ENOUGH for enterprise as quoted
A14: Biggest limitation | B14: TikTok competitor analysis costs an extra $150,000; 15–20 brands & keyword tracking are unpriced custom work | C14: 15,000 advanced influencer profiles / year, 8 logins, 25,000 comments / month; 5 of 6 prices pending | D14: 200 campaigns & 200 ROI reports / year; 3,000 posts & 10,000 comments / month; outreach modules '–'
A15: Key strengths | B15: Already in use; history extended to 2 years; CPE / CPM / ROI in Campaign Management; CPV / CTR / VTR committed for Q3 | C15: Lowest price; most volumes 'Unlimited'; full end-to-end workflow with AI automation; 30-person Indonesia team; comment-level sentiment | D15: All 6 options priced with clear terms; ID + TH coverage; explicit caps and SLA; DocuSeal e-sign; named CSM
A17: Key takeaways
A18: ="Price: on the like-for-like 12-month Indonesia option, Viral Pitch costs "&TEXT(Pricing!F7,"$#,##0")&", HypeAuditor "&TEXT(Pricing!J7,"$#,##0")&" and CultureX "&TEXT(Pricing!I7,"$#,##0")&". Adding HypeAuditor's $150,000 TikTok build brings its year-1 cost to "&TEXT(Pricing!D27,"$#,##0")&", about "&TEXT(Pricing!D28,"0.0")&"× Viral Pitch." -> Price: on the like-for-like 12-month Indonesia option, Viral Pitch costs $35,988, HypeAuditor $55,000 and CultureX $54,000. Adding HypeAuditor's $150,000 TikTok build brings its year-1 cost to $205,000, about 5.7× Viral Pitch.
A19: HypeAuditor is the weakest fit on features: 4 High-severity gaps (TikTok competitor analysis, 5-brand limit, no keyword tracking, no comment-level sentiment). Closing them costs $150,000 plus custom work it hasn't priced.
A20: CultureX has the tightest volumes. At the assumed enterprise usage, most of its capped modules (campaigns, ROI reports, post & comment analysis, hashtags, CRM) come in below need, and its outreach modules are '–'.
A21: Viral Pitch has the fewest volume limits. The ones to negotiate before signing: 15,000 advanced profiles / year, 8 logins, 25,000 comments / month, and firm prices for the other 5 options.
A22: Change the yellow assumption cells on 'Limitations & Enterprise Fit' to match Dentsu's real volumes. Every flag and verdict recalculates.
A24: Sources
A25: Viral Pitch: Viral_Pitch_Dentsu_Proposal_3.pptx (Sep 2026), slides 7–20 and 34–36
A26: CultureX: 'CX <> Dentsu Indonesia_Enterprise UNLIMITED Plan_2026' Google Sheet (screenshots provided 30 Sep 2026)
A27: HypeAuditor: Dentsu__Hypeauditor_Feature_Feedback.xlsx (12 feedback items with HypeAuditor responses and add-on quotes); $55k / yr baseline provided by user

Sheet Pricing
A1: Pricing Comparison — 6 RFP Contract Options (USD, excl. tax)
A2: Blue = figures from vendor documents. Black = formulas. Viral Pitch: only the 12-month Indonesia option is confirmed (slides 15 & 36). CultureX: the '6 Contract Options' sheet. HypeAuditor: $55,000 / year baseline provided by you (12-month option only) plus its add-on quotes.
A4: Option | B4: Market scope | C4: Term (months) | D4: Viral Pitch Total contract | E4: Viral Pitch Monthly equiv. | F4: Viral Pitch Annual equiv. | G4: CultureX Total contract | H4: CultureX Monthly equiv. | I4: CultureX Annual equiv. | J4: HypeAuditor Total contract | K4: HypeAuditor Monthly equiv. | L4: CultureX vs Viral Pitch (annual difference) | N4: Viral Pitch confirmed monthly rate | O4: Note
A5: Option 1 | B5: Indonesia only (6-mo pilot, +25%) | C5: 6 | D5: In progress | E5: In progress | F5: In progress | G5: 33750 | H5: =G5/C5 -> 5625 | I5: =G5/C5*12 -> 67500 | J5: Not quoted | K5: =IF(ISNUMBER(J5),J5/C5,"Not quoted") -> Not quoted | L5: =IF(AND(ISNUMBER(F5),ISNUMBER(I5)),I5-F5,"n/a") -> n/a | N5: 2999 | O5: Used for Option 3 only. The other 5 options are 'In progress' per Viral Pitch.
A6: Option 2 | B6: Indonesia + Thailand (6-mo pilot) | C6: 6 | D6: In progress | E6: In progress | F6: In progress | G6: 44888 | H6: =G6/C6 -> 7481.3333 | I6: =G6/C6*12 -> 89776 | J6: Not quoted | K6: =IF(ISNUMBER(J6),J6/C6,"Not quoted") -> Not quoted | L6: =IF(AND(ISNUMBER(F6),ISNUMBER(I6)),I6-F6,"n/a") -> n/a
A7: Option 3 | B7: Indonesia only | C7: 12 | D7: =$N$5*C7 -> 35988 | E7: =IF(ISNUMBER(D7),D7/C7,"In progress") -> 2999 | F7: =IF(ISNUMBER(D7),D7/C7*12,"In progress") -> 35988 | G7: 54000 | H7: =G7/C7 -> 4500 | I7: =G7/C7*12 -> 54000 | J7: =$N$8*C7/12 -> 55000 | K7: =IF(ISNUMBER(J7),J7/C7,"Not quoted") -> 4583.3333 | L7: =IF(AND(ISNUMBER(F7),ISNUMBER(I7)),I7-F7,"n/a") -> 18012 | N7: HypeAuditor baseline annual price
A8: Option 4 | B8: Indonesia + Thailand | C8: 12 | D8: In progress | E8: In progress | F8: In progress | G8: 71820 | H8: =G8/C8 -> 5985 | I8: =G8/C8*12 -> 71820 | J8: Not quoted | K8: =IF(ISNUMBER(J8),J8/C8,"Not quoted") -> Not quoted | L8: =IF(AND(ISNUMBER(F8),ISNUMBER(I8)),I8-F8,"n/a") -> n/a | N8: 55000 | O8: Annual baseline, applied to the 12-month option. HypeAuditor hasn't quoted the other options.
A9: Option 5 | B9: Indonesia only (24-mo, −15%) | C9: 24 | D9: In progress | E9: In progress | F9: In progress | G9: 91800 | H9: =G9/C9 -> 3825 | I9: =G9/C9*12 -> 45900 | J9: Not quoted | K9: =IF(ISNUMBER(J9),J9/C9,"Not quoted") -> Not quoted | L9: =IF(AND(ISNUMBER(F9),ISNUMBER(I9)),I9-F9,"n/a") -> n/a
A10: Option 6 | B10: Indonesia + Thailand (24-mo, −15%) | C10: 24 | D10: In progress | E10: In progress | F10: In progress | G10: 122094 | H10: =G10/C10 -> 5087.25 | I10: =G10/C10*12 -> 61047 | J10: Not quoted | K10: =IF(ISNUMBER(J10),J10/C10,"Not quoted") -> Not quoted | L10: =IF(AND(ISNUMBER(F10),ISNUMBER(I10)),I10-F10,"n/a") -> n/a
A12: Like-for-like: Option 3 (12 months, Indonesia only), base licence
A13: Viral Pitch annual | C13: =F7 -> 35988
A14: CultureX annual | C14: =I7 -> 54000
A15: HypeAuditor annual (baseline) | C15: =J7 -> 55000
A16: CultureX premium over Viral Pitch (USD) | C16: =I7-F7 -> 18012
A17: CultureX premium over Viral Pitch (%) | C17: =(I7-F7)/F7 -> 0.50050017
A18: HypeAuditor premium over Viral Pitch (USD) | C18: =J7-F7 -> 19012
A19: HypeAuditor premium over Viral Pitch (%) | C19: =(J7-F7)/F7 -> 0.52828721
A20: Viral Pitch saving vs CultureX (%) | C20: =(I7-F7)/I7 -> 0.33355556
A22: Year-1 cost to meet Dentsu's requirements (12 months, Indonesia)
A23: Cost line | D23: HypeAuditor | E23: Viral Pitch | F23: CultureX | G23: Comment
A24: Base licence (annual) | D24: =J7 -> 55000 | E24: =F7 -> 35988 | F24: =I7 -> 54000 | G24: 12-month Indonesia option
A25: TikTok competitor analysis | D25: =D42 -> 150000 | E25: Included | F25: Included | G25: HypeAuditor: $150,000 custom build. Viral Pitch & CultureX: included in plan
A26: 15–20 brand comparison + keyword / Boolean tracking | D26: Not priced | E26: No extra cost quoted | F26: No extra cost quoted | G26: HypeAuditor: custom development, 'additional investment' not yet quoted. Viral Pitch / CultureX: no add-on fee, but Boolean keyword tracking isn't confirmed in either document
A27: Total known year-1 cost | D27: =SUM(D24:D26) -> 205000 | E27: =SUM(E24:E26) -> 35988 | F27: =SUM(F24:F26) -> 54000 | G27: HypeAuditor total excludes the unpriced custom work, so the real figure is higher
A28: Multiple of Viral Pitch cost | D28: =D27/E27 -> 5.6963432 | E28: =E27/E27 -> 1 | F28: =F27/E27 -> 1.5005002
A30: Commercial terms
A31: Term | D31: HypeAuditor | G31: Viral Pitch | J31: CultureX
A32: Pricing status | D32: Baseline $55,000 / year (provided by user); add-ons quoted separately | G32: 1 of 6 options confirmed; 5 in progress | J32: All 6 options priced
A33: Payment structure | D33: Not stated | G33: Not stated | J33: 100% in advance (6 & 12 months); 24 months paid in two annual tranches (50% each)
A34: Taxes | D34: Not stated | G34: To be itemised in final commercial submission | J34: Excluded (all prices exclude applicable taxes)
A35: Pricing model | D35: Annual licence plus custom-development fees for gaps | G35: Modular platform licence; 'Unlimited' items under fair-usage policy | J35: One enterprise plan with all modules; pilot +25%; ID+TH +33%; 24-month −15% with price lock
A36: Exclusions / extras | D36: TikTok competitor analysis $150,000 (custom); extra history $36,000 / yr per year; 15–20 brands & keyword tracking = custom dev (unpriced) | G36: Final quote to itemise implementation, onboarding, training, support, API access, data limits, optional modules and third-party charges | J36: WhatsApp Business API charges (passed through at cost); custom development; credit top-ups if annual allocations are exceeded
A37: Usage controls | D37: Not stated | G37: Fair-usage policy | J37: Quarterly usage review; 30-day good-faith talks, then CultureX may propose a plan amendment on 60 days' notice
A39: Note: CultureX's own sheet shows Option 2 annual value as $89,775 (rounding). The formula here gives $89,776.
A40: HypeAuditor add-on quotes (from Dentsu Hypeauditor Feature Feedback, HypeAuditor Response column)
A41: # | B41: Add-on | D41: Cost (USD) | E41: Basis | H41: Status
A42: 1 & 6 | B42: TikTok competitor analysis (SOV, comparisons, exports) | D42: 150000 | E42: One-off custom development | H42: Outside standard roadmap
A43: 4 | B43: Each additional year of history beyond 2 years | D43: 36000 | E43: Per extra year, per year | H43: 2 years already extended at no stated cost
A44: 3 | B44: Compare 15–20 competitor brands | D44: Not priced | E44: Custom development | H44: 'Additional investment' required
A45: 7 | B45: Keyword & Boolean keyword tracking | D45: Not priced | E45: Custom development after R&D | H45: 'Additional implementation cost'
...

Sheet Limitations & Enterprise Fit
A1: Limitations & Enterprise-Scale Check
A2: Each vendor's caps are compared with an enterprise usage profile for Dentsu Influence Indonesia. The yellow cells are assumptions: edit them and every status and flag recalculates. 'Enough' means the cap covers the need with the headroom set in B20.
A4: A. Enterprise usage assumptions (edit the yellow cells)
A5: Campaigns per year | B5: 300 | C5: Assumption: ~25 campaigns / month across ID + TH advertiser clients
A6: Active advertiser clients | B6: 30 | C6: Assumption
A7: Creators vetted per campaign (deep profile) | B7: 50 | C7: Assumption: shortlist depth before contracting
A8: Pitches / QBRs needing creator research per year | B8: 100 | C8: Assumption: new business + QBRs (listed as an objective in the RFP brief)
A9: Creators researched per pitch | B9: 30 | C9: Assumption
A10: Brand & competitor accounts monitored | B10: 150 | C10: Assumption: ~5 brand / competitor accounts per client
A11: Posts per monitored account per month | B11: 30 | C11: Assumption: ~1 post / day
A12: Posts needing comment-level sentiment per month | B12: 300 | C12: Assumption: key posts for client reporting & crisis checks
A13: Comments analysed per post | B13: 100 | C13: Dentsu requirement: 'at least the top 100 comments' per post
A14: Competitor reports per client per year | B14: 4 | C14: Assumption: quarterly
A15: Competitor brands per comparison | B15: 15 | C15: Dentsu requirement: at least 15–20 brands
A16: Hashtags tracked at the same time | B16: 150 | C16: Assumption: live-campaign hashtags + always-on brand hashtags
... A20: Headroom required on usage caps | B20: 1.25 | C20: A cap must cover 125% of the need to count as 'Enough'; 100–125% = 'Tight'
A22: B. Capacity check: included volume vs enterprise need
A23: Metric | B23: Enterprise need | C23: Headroom applies? | D23: HypeAuditor cap | E23: HA coverage | F23: HA status | G23: Viral Pitch cap | H23: VP coverage | I23: VP status | J23: CultureX cap | K23: CX coverage | L23: CX status | M23: How the need is calculated / note
A24: Advanced creator profiles / year | B24: =$B$5*$B$7+$B$8*$B$9 -> 18000 | C24: Y | D24: Not stated | E24: =IF(ISNUMBER(D24),D24/$B24,"") | F24: =IF(D24="Unlimited","Enough (fair use)",IF(D24="Not offered","Not enough",IF(ISNUMBER(D24),IF(D24>=$B24*IF($C24="Y",$B$20,1),"Enough",IF(D24>=$B24,"Tight","Not enough")),"Unknown"))) -> Unknown | G24: 15000 | H24: =IF(ISNUMBER(G24),G24/$B24,"") -> 0.83333333 | I24: =IF(G24="Unlimited","Enough (fair use)",IF(G24="Not offered","Not enough",IF(ISNUMBER(G24),IF(G24>=$B24*IF($C24="Y",$B$20,1),"Enough",IF(G24>=$B24,"Tight","Not enough")),"Unknown"))) -> Not enough | J24: Not shown | K24: =IF(ISNUMBER(J24),J24/$B24,"") | L24: =IF(J24="Unlimited","Enough (fair use)",IF(J24="Not offered","Not enough",IF(ISNUMBER(J24),IF(J24>=$B24*IF($C24="Y",$B$20,1),"Enough",IF(J24>=$B24,"Tight","Not enough")),"Unknown"))) -> Unknown | M24: Campaigns × creators vetted + pitches × creators researched
A25: Live campaigns / year | B25: =$B$5 -> 300 | C25: Y | D25: Not stated | E25: =IF(ISNUMBER(D25),D25/$B25,"") | F25: =IF(D25="Unlimited","Enough (fair use)",IF(D25="Not offered","Not enough",IF(ISNUMBER(D25),IF(D25>=$B25*IF($C25="Y",$B$20,1),"Enough",IF(D25>=$B25,"Tight","Not enough")),"Unknown"))) -> Unknown | G25: Unlimited | H25: =IF(ISNUMBER(G25),G25/$B25,"") | I25: =IF(G25="Unlimited","Enough (fair use)",IF(G25="Not offered","Not enough",IF(ISNUMBER(G25),IF(G25>=$B25*IF($C25="Y",$B$20,1),"Enough",IF(G25>=$B25,"Tight","Not enough")),"Unknown"))) -> Enough (fair use) | J25: 200 | K25: =IF(ISNUMBER(J25),J25/$B25,"") -> 0.66666667 | L25: =IF(J25="Unlimited","Enough (fair use)",IF(J25="Not offered","Not enough",IF(ISNUMBER(J25),IF(J25>=$B25*IF($C25="Y",$B$20,1),"Enough",IF(J25>=$B25,"Tight","Not enough")),"Unknown"))) -> Not enough | M25: One tracked campaign per activation
A26: ROI / campaign reports / year | B26: =$B$5+$B$6*12 -> 660 | C26: Y | D26: Not stated | E26: =IF(ISNUMBER(D26),D26/$B26,"") | F26: =IF(D26="Unlimited","Enough (fair use)",IF(D26="Not offered","Not enough",IF(ISNUMBER(D26),IF(D26>=$B26*IF($C26="Y",$B$20,1),"Enough",IF(D26>=$B26,"Tight","Not enough")),"Unknown"))) -> Unknown | G26: Unlimited | H26: =IF(ISNUMBER(G26),G26/$B26,"") | I26: =IF(G26="Unlimited","Enough (fair use)",IF(G26="Not offered","Not enough",IF(ISNUMBER(G26),IF(G26>=$B26*IF($C26="Y",$B$20,1),"Enough",IF(G26>=$B26,"Tight","Not enough")),"Unknown"))) -> Enough (fair use) | J26: 200 | K26: =IF(ISNUMBER(J26),J26/$B26,"") -> 0.3030303 | L26: =IF(J26="Unlimited","Enough (fair use)",IF(J26="Not offered","Not enough",IF(ISNUMBER(J26),IF(J26>=$B26*IF($C26="Y",$B$20,1),"Enough",IF(J26>=$B26,"Tight","Not enough")),"Unknown"))) -> Not enough | M26: One per campaign + a monthly report per client
A27: Post analysis / month | B27: =$B$10*$B$11 -> 4500 | C27: Y | D27: Not stated | E27: =IF(ISNUMBER(D27),D27/$B27,"") | F27: =IF(D27="Unlimited","Enough (fair use)",IF(D27="Not offered","Not enough",IF(ISNUMBER(D27),IF(D27>=$B27*IF($C27="Y",$B$20,1),"Enough",IF(D27>=$B27,"Tight","Not enough")),"Unknown"))) -> Unknown | G27: 10000 | H27: =IF(ISNUMBER(G27),G27/$B27,"") -> 2.2222222 | I27: =IF(G27="Unlimited","Enough (fair use)",IF(G27="Not offered","Not enough",IF(ISNUMBER(G27),IF(G27>=$B27*IF($C27="Y",$B$20,1),"Enough",IF(G27>=$B27,"Tight","Not enough")),"Unknown"))) -> Enough | J27: 3000 | K27: =IF(ISNUMBER(J27),J27/$B27,"") -> 0.66666667 | L27: =IF(J27="Unlimited","Enough (fair use)",IF(J27="Not offered","Not enough",IF(ISNUMBER(J27),IF(J27>=$B27*IF($C27="Y",$B$20,1),"Enough",IF(J27>=$B27,"Tight","Not enough")),"Unknown"))) -> Not enough | M27: Monitored accounts × posts per account
A28: Comment analysis / month | B28: =$B$12*$B$13 -> 30000 | C28: Y | D28: Not offered | E28: =IF(ISNUMBER(D28),D28/$B28,"") | F28: =IF(D28="Unlimited","Enough (fair use)",IF(D28="Not offered","Not enough",IF(ISNUMBER(D28),IF(D28>=$B28*IF($C28="Y",$B$20,1),"Enough",IF(D28>=$B28,"Tight","Not enough")),"Unknown"))) -> Not enough | G28: 25000 | H28: =IF(ISNUMBER(G28),G28/$B28,"") -> 0.83333333 | I28: =IF(G28="Unlimited","Enough (fair use)",IF(G28="Not offered","Not enough",IF(ISNUMBER(G28),IF(G28>=$B28*IF($C28="Y",$B$20,1),"Enough",IF(G28>=$B28,"Tight","Not enough")),"Unknown"))) -> Not enough | J28: 10000 | K28: =IF(ISNUMBER(J28),J28/$B28,"") -> 0.33333333 | L28: =IF(J28="Unlimited","Enough (fair use)",IF(J28="Not offered","Not enough",IF(ISNUMBER(J28),IF(J28>=$B28*IF($C28="Y",$B$20,1),"Enough",IF(J28>=$B28,"Tight","Not enough")),"Unknown"))) -> Not enough | M28: Key posts × comments per post. HypeAuditor declined comment-level access
A29: Competitor brands per comparison | B29: =$B$15 -> 15 | C29: N | D29: 5 | E29: =IF(ISNUMBER(D29),D29/$B29,"") -> 0.33333333 | F29: =IF(D29="Unlimited","Enough (fair use)",IF(D29="Not offered","Not enough",IF(ISNUMBER(D29),IF(D29>=$B29*IF($C29="Y",$B$20,1),"Enough",IF(D29>=$B29,"Tight","Not enough")),"Unknown"))) -> Not enough | G29: Unlimited | H29: =IF(ISNUMBER(G29),G29/$B29,"") | I29: =IF(G29="Unlimited","Enough (fair use)",IF(G29="Not offered","Not enough",IF(ISNUMBER(G29),IF(G29>=$B29*IF($C29="Y",$B$20,1),"Enough",IF(G29>=$B29,"Tight","Not enough")),"Unknown"))) -> Enough (fair use) | J29: Not stated | K29: =IF(ISNUMBER(J29),J29/$B29,"") | L29: =IF(J29="Unlimited","Enough (fair use)",IF(J29="Not offered","Not enough",IF(ISNUMBER(J29),IF(J29>=$B29*IF($C29="Y",$B$20,1),"Enough",IF(J29>=$B29,"Tight","Not enough")),"Unknown"))) -> Unknown | M29: Dentsu requirement
A30: Competitor reports / year | B30: =$B$6*$B$14 -> 120 | C30: Y | D30: Not stated | E30: =IF(ISNUMBER(D30),D30/$B30,"") | F30: =IF(D30="Unlimited","Enough (fair use)",IF(D30="Not offered","Not enough",IF(ISNUMBER(D30),IF(D30>=$B30*IF($C30="Y",$B$20,1),"Enough",IF(D30>=$B30,"Tight","Not enough")),"Unknown"))) -> Unknown | G30: Unlimited | H30: =IF(ISNUMBER(G30),G30/$B30,"") | I30: =IF(G30="Unlimited","Enough (fair use)",IF(G30="Not offered","Not enough",IF(ISNUMBER(G30),IF(G30>=$B30*IF($C30="Y",$B$20,1),"Enough",IF(G30>=$B30,"Tight","Not enough")),"Unknown"))) -> Enough (fair use) | J30: 100 | K30: =IF(ISNUMBER(J30),J30/$B30,"") -> 0.83333333 | L30: =IF(J30="Unlimited","Enough (fair use)",IF(J30="Not offered","Not enough",IF(ISNUMBER(J30),IF(J30>=$B30*IF($C30="Y",$B$20,1),"Enough",IF(J30>=$B30,"Tight","Not enough")),"Unknown"))) -> Not enough | M30: Clients × reports per client (CultureX 'Competitor Watch')
A31: Hashtags tracked at the same time | B31: =$B$16 -> 150 | C31: Y | D31: Not stated | E31: =IF(ISNUMBER(D31),D31/$B31,"") | F31: =IF(D31="Unlimited","Enough (fair use)",IF(D31="Not offered","Not enough",IF(ISNUMBER(D31),IF(D31>=$B31*IF($C31="Y",$B$20,1),"Enough",IF(D31>=$B31,"Tight","Not enough")),"Unknown"))) -> Unknown | G31: Unlimited | H31: =IF(ISNUMBER(G31),G31/$B31,"") | I31: =IF(G31="Unlimited","Enough (fair use)",IF(G31="Not offered","Not enough",IF(ISNUMBER(G31),IF(G31>=$B31*IF($C31="Y",$B$20,1),"Enough",IF(G31>=$B31,"Tight","Not enough")),"Unknown"))) -> Enough (fair use) | J31: 100 | K31: =IF(ISNUMBER(J31),J31/$B31,"") -> 0.66666667 | L31: =IF(J31="Unlimited","Enough (fair use)",IF(J31="Not offered","Not enough",IF(ISNUMBER(J31),IF(J31>=$B31*IF($C31="Y",$B$20,1),"Enough",IF(J31>=$B31,"Tight","Not enough")),"Unknown"))) -> Not enough | M31: CultureX: 100 active at once (swap pool 200 / month)
A32: Brand accounts monitored at the same time | B32: =$B$10 -> 150 | C32: Y | D32: Not stated | E32: =IF(ISNUMBER(D32),D32/$B32,"") | F32: =IF(D32="Unlimited","Enough (fair use)",IF(D32="Not offered","Not enough",IF(ISNUMBER(D32),IF(D32>=$B32*IF($C32="Y",$B$20,1),"Enough",IF(D32>=$B32,"Tight","Not enough")),"Unknown"))) -> Unknown | G32: Unlimited | H32: =IF(ISNUMBER(G32),G32/$B32,"") | I32: =IF(G32="Unlimited","Enough (fair use)",IF(G32="Not offered","Not enough",IF(ISNUMBER(G32),IF(G32>=$B32*IF($C32="Y",$B$20,1),"Enough",IF(G32>=$B32,"Tight","Not enough")),"Unknown"))) -> Enough (fair use) | J32: 500 | K32: =IF(ISNUMBER(J32),J32/$B32,"") -> 3.3333333 | L32: =IF(J32="Unlimited","Enough (fair use)",IF(J32="Not offered","Not enough",IF(ISNUMBER(J32),IF(J32>=$B32*IF($C32="Y",$B$20,1),"Enough",IF(J32>=$B32,"Tight","Not enough")),"Unknown"))) -> Enough | M32: CultureX: 500 active at once
A33: Creators held in CRM | B33: =$B$18 -> 15000 | C33: Y | D33: Not stated | E33: =IF(ISNUMBER(D33),D33/$B33,"") | F33: =IF(D33="Unlimited","Enough (fair use)",IF(D33="Not offered","Not enough",IF(ISNUMBER(D33),IF(D33>=$B33*IF($C33="Y",$B$20,1),"Enough",IF(D33>=$B33,"Tight","Not enough")),"Unknown"))) -> Unknown | G33: Unlimited | H33: =IF(ISNUMBER(G33),G33/$B33,"") | I33: =IF(G33="Unlimited","Enough (fair use)",IF(G33="Not offered","Not enough",IF(ISNUMBER(G33),IF(G33>=$B33*IF($C33="Y",$B$20,1),"Enough",IF(G33>=$B33,"Tight","Not enough")),"Unknown"))) -> Enough (fair use) | J33: 10000 | K33: =IF(ISNUMBER(J33),J33/$B33,"") -> 0.66666667 | L33: =IF(J33="Unlimited","Enough (fair use)",IF(J33="Not offered","Not enough",IF(ISNUMBER(J33),IF(J33>=$B33*IF($C33="Y",$B$20,1),"Enough",IF(J33>=$B33,"Tight","Not enough")),"Unknown"))) -> Not enough
A34: Platform user logins | B34: =$B$17 -> 15 | C34: N | D34: Not stated | E34: =IF(ISNUMBER(D34),D34/$B34,"") | F34: =IF(D34="Unlimited","Enough (fair use)",IF(D34="Not offered","Not enough",IF(ISNUMBER(D34),IF(D34>=$B34*IF($C34="Y",$B$20,1),"Enough",IF(D34>=$B34,"Tight","Not enough")),"Unknown"))) -> Unknown | G34: 8 | H34: =IF(ISNUMBER(G34),G34/$B34,"") -> 0.53333333 | I34: =IF(G34="Unlimited","Enough (fair use)",IF(G34="Not offered","Not enough",IF(ISNUMBER(G34),IF(G34>=$B34*IF($C34="Y",$B$20,1),"Enough",IF(G34>=$B34,"Tight","Not enough")),"Unknown"))) -> Not enough | J34: Not shown | K34: =IF(ISNUMBER(J34),J34/$B34,"") | L34: =IF(J34="Unlimited","Enough (fair use)",IF(J34="Not offered","Not enough",IF(ISNUMBER(J34),IF(J34>=$B34*IF($C34="Y",$B$20,1),"Enough",IF(J34>=$B34,"Tight","Not enough")),"Unknown"))) -> Unknown | M34: Viral Pitch: 8 team logins (+10 operator dashboards)
A35: Months of historical data | B35: =$B$19 -> 24 | C35: N | D35: 24 | E35: =IF(ISNUMBER(D35),D35/$B35,"") -> 1 | F35: =IF(D35="Unlimited","Enough (fair use)",IF(D35="Not offered","Not enough",IF(ISNUMBER(D35),IF(D35>=$B35*IF($C35="Y",$B$20,1),"Enough",IF(D35>=$B35,"Tight","Not enough")),"Unknown"))) -> Enough | G35: 24 | H35: =IF(ISNUMBER(G35),G35/$B35,"") -> 1 | I35: =IF(G35="Unlimited","Enough (fair use)",IF(G35="Not offered","Not enough",IF(ISNUMBER(G35),IF(G35>=$B35*IF($C35="Y",$B$20,1),"Enough",IF(G35>=$B35,"Tight","Not enough")),"Unknown"))) -> Enough | J35: Not stated | K35: =IF(ISNUMBER(J35),J35/$B35,"") | L35: =IF(J35="Unlimited","Enough (fair use)",IF(J35="Not offered","Not enough",IF(ISNUMBER(J35),IF(J35>=$B35*IF($C35="Y",$B$20,1),"Enough",IF(J35>=$B35,"Tight","Not enough")),"Unknown"))) -> Unknown | M35: HypeAuditor: extended to 2 yrs. Viral Pitch: 24-month migration
A37: C. Limitations register (capacity rows follow section B; High = coverage below 75% of need or a blocking gap)
A38: Vendor | B38: Limitation | D38: Impact at enterprise scale | J38: Severity | K38: Type | M38: Source
A39: HypeAuditor | B39: TikTok competitor analysis not in product | D39: Needs a $150,000 custom build, about 2.7× the annual licence | J39: High | K39: Add-on cost | M39: HA response #1 / #6
A40: HypeAuditor | B40: 5 brands per competitor comparison | D40: Dentsu needs 15–20. The upgrade is custom development and not yet priced | J40: =IF(F29="Not enough",IF(AND(ISNUMBER(E29),E29>=0.75),"Medium","High"),IF(F29="Tight","Low",IF(F29="Unknown","Check","OK"))) -> High | K40: Capacity | M40: HA response #3
A41: HypeAuditor | B41: No keyword / Boolean tracking | D41: Hashtag-only tracking misses creator content that doesn't use the official hashtag. Custom development, unpriced | J41: High | K41: Feature gap | M41: HA response #7
A42: HypeAuditor | B42: Comment-level sentiment declined | D42: Sentiment can't be audited or backed with example comments for clients or crisis work | J42: High | K42: Feature gap | M42: HA response #5
A43: HypeAuditor | B43: Shares / saves manual only; static-post impressions not until Q4 | D43: Reports on static content stay incomplete; the team has to enter data by hand | J43: Medium | K43: Feature gap | M43: HA response #8 / #9
A44: HypeAuditor | B44: No Spark Ads data | D44: Paid amplification is left out of TikTok reporting | J44: Medium | K44: Feature gap | M44: HA response #11
A45: HypeAuditor | B45: History beyond 2 years: $36,000 / year per extra year | D45: Only matters if more than 2 years of trend data is needed | J45: Low | K45: Add-on cost | M45: HA response #4
A46: Viral Pitch | B46: 15,000 advanced influencer profiles / year | D46: About 1,250 deep profiles a month across all clients and pitches | J46: =IF(I24="Not enough",IF(AND(ISNUMBER(H24),H24>=0.75),"Medium","High"),IF(I24="Tight","Low",IF(I24="Unknown","Check","OK"))) -> Medium | K46: Capacity | M46: VP slide 16
...

Sheet Dentsu Requirements Fit
A1: Fit Against Dentsu's 12 Requirements (the gaps raised on HypeAuditor)
A2: Requirements come from Dentsu__Hypeauditor_Feature_Feedback.xlsx; HypeAuditor ratings reflect its own responses. Ratings are based only on what each vendor document states: Meets / Partial / Gap / Not confirmed ('Not confirmed' means the source doesn't mention it; ask the vendor).
A4: # | B4: Requirement | C4: HypeAuditor | D4: HypeAuditor — evidence | E4: Viral Pitch | F4: Viral Pitch — evidence | G4: CultureX | H4: CultureX — evidence
A5: 1 | B5: Cross-platform competitor analysis (TikTok, YouTube, X, Threads) | C5: Partial | D5: Instagram-led. TikTok competitor analysis only as custom development: $150,000 quoted | E5: Partial | F5: Competitors Watch covers IG / YouTube / TikTok (rated Strong); X & Threads 'limited today', on near-term roadmap | G5: Partial | H5: Brand monitoring across Instagram, TikTok & YouTube (ID + TH); X / Threads not listed
A6: 2 | B6: Benchmarking metrics: CPV, CTR, VTR, CPE (manual cost input) | C6: Partial | D6: CPE, CPM & ROI auto-calculated in Campaign Management once budget is entered; CPV / CTR / VTR input committed for Q3 | E6: Partial | F6: UTM tracking (clicks, conversions, revenue per creator); creator costs in Media Plans; efficiency vs past performance. CPV / VTR benchmarking not explicitly stated | G6: Partial | H6: UTM Tracking Tool included; cost-based efficiency metrics not stated
A7: 3 | B7: Compare 15–20+ competitor brands | C7: Partial | D7: Still 5 brands. 15–20 needs custom development plus extra investment (not priced) | E7: Meets | F7: Competitors Watch: Unlimited (fair-usage policy) | G7: Meets | H7: 100 competitor watches / yr; up to 500 brand accounts monitored simultaneously
A8: 4 | B8: At least 2 years of historical data | C8: Meets | D8: Extended to 2 years. Each extra year: $36,000 / year | E8: Partial | F8: Migration of up to 24 months of your historical data; platform's own history depth not quantified | G8: Not confirmed | H8: Not stated in plan
A9: 5 | B9: Comment-level sentiment transparency | C9: Gap | D9: Declined: won't expose comment-level sentiment (cites quality / accuracy of single-comment classification) | E9: Meets | F9: Comment-level sentiment in ROI reports; Comment Analysis 25,000 / month | G9: Meets | H9: Comment Analysis 10,000 / month; comment export for internal client use
A10: 6 | B10: TikTok competitor intelligence (SOV, comparisons, exports) | C10: Gap | D10: Not in product. Custom development quoted at $150,000 | E10: Meets | F10: Competitors Watch with Share-of-Voice; TikTok coverage rated Strong | G10: Meets | H10: TikTok in monitoring suite; Competitor Watch; 100 Market Benchmarking PDFs / yr; CSV / PDF export
A11: 7 | B11: Keyword & Boolean keyword tracking (not just hashtags) | C11: Gap | D11: Hashtag only. Keyword / Boolean needs R&D and custom development at extra cost (not priced) | E11: Partial | F11: Brand, category & hashtag-level monitoring plus mentions; Boolean logic not stated | G11: Not confirmed | H11: Hashtag tracking shown; keyword / Boolean not stated
A12: 8 | B12: Shares & saves metrics | C12: Partial | D12: Not collected (private Meta metrics). Can be entered manually in Campaigns if creators share them | E12: Partial | F12: Share metrics listed; saves not stated | G12: Not confirmed | H12: Not stated in plan
A13: 9 | B13: Performance data for static posts (e.g. est. impressions) | C13: Gap | D13: Impressions are private, so static posts show blank. Estimated Impressions planned for Q4 | E13: Partial | F13: Estimated reach tracked per post in ROI reports; static-post handling to confirm in demo | G13: Not confirmed | H13: Not stated in plan
A14: 10 | B14: End-to-end campaign management workflow | C14: Partial | D14: Responded 'Done' (sorting & filtering added); Campaign Management exists. Outreach / contracting not evidenced | E14: Meets | F14: Media plans, bulk outreach, AI negotiation, content audit, live campaigns, ROI reports — all included | G14: Partial | H14: Live Campaign Dashboard (200 / yr), DocuSeal e-sign, ROI reports; Bulk Email, WhatsApp & Media Plans shown as '–'
A15: 11 | B15: TikTok Spark Ads / Ads integration & conversion tracking | C15: Partial | D15: Conversion tracking via custom links / promo codes; Spark Ads not available (not public data) | E15: Not confirmed | F15: Not stated (UTM conversion tracking only) | G15: Not confirmed | H15: Not stated (UTM tracking only)
A16: 12 | B16: Social listening & competitive intelligence depth | C16: Gap | D16: No commitment yet: HypeAuditor asked Dentsu to specify what's needed | E16: Meets | F16: Category intelligence (needs taxonomy, trends, SOV, cultural insight); configured per client / market | G16: Partial | H16: Brand, hashtag & competitor tracking; plan states it is 'representative, not exhaustive' social listening
B18: Tally
B19: Rating | C19: HypeAuditor | E19: Viral Pitch | G19: CultureX
B20: Meets | C20: =COUNTIF(C$5:C$16,$B20) -> 1 | E20: =COUNTIF(E$5:E$16,$B20) -> 5 | G20: =COUNTIF(G$5:G$16,$B20) -> 3
B21: Partial | C21: =COUNTIF(C$5:C$16,$B21) -> 6 | E21: =COUNTIF(E$5:E$16,$B21) -> 6 | G21: =COUNTIF(G$5:G$16,$B21) -> 4
B22: Gap | C22: =COUNTIF(C$5:C$16,$B22) -> 5 | E22: =COUNTIF(E$5:E$16,$B22) -> 0 | G22: =COUNTIF(G$5:G$16,$B22) -> 0
B23: Not confirmed | C23: =COUNTIF(C$5:C$16,$B23) -> 0 | E23: =COUNTIF(E$5:E$16,$B23) -> 1 | G23: =COUNTIF(G$5:G$16,$B23) -> 5

Sheet Features & Volumes
A1: Feature & Included-Volume Comparison
A2: Viral Pitch: proposal slides 15–20, 34–35. CultureX: Enterprise UNLIMITED plan screenshots (some rows weren't visible, marked 'Not shown in screenshots'). HypeAuditor: feedback file and its responses only, so features they don't discuss read 'Not covered in feedback file'.
A4: Category | B4: Feature | C4: HypeAuditor | D4: Viral Pitch | E4: CultureX
A5: SCOPE & ACCESS
A6: Scope & access | B6: Markets in quote | C6: Current licence (base price TBC) | D6: Indonesia (ID + TH options still being finalised) | E6: Indonesia + Thailand options priced
A7: Scope & access | B7: Platforms | C7: Instagram-led competitor analysis; TikTok competitor analysis = $150,000 custom build | D7: Instagram, YouTube, TikTok (Strong); X & Threads limited | E7: Instagram, TikTok, YouTube
A8: Scope & access | B8: Team logins | C8: Not covered in feedback file | D8: 8 logins + 10 agency-operator dashboards | E8: Not shown in screenshots
A9: Scope & access | B9: White-labelling | C9: Not covered in feedback file | D9: Full platform white-label (Dentsu logo, fonts, colours) | E9: White-labelled shareable links (client-facing only)
A10: CREATOR DISCOVERY
A11: Creator discovery | B11: Creator search | C11: Not covered in feedback file | D11: Unlimited global search (IG / YT / TT) + unlimited basic data | E11: Unlimited discovery lists
A12: Creator discovery | B12: Advanced creator profiles | C12: Not covered in feedback file | D12: 15,000 / year | E12: Not shown in screenshots
A13: Creator discovery | B13: Fraud / fake-follower detection | C13: Not covered in feedback file | D13: Authenticity signal live; deeper AI fraud scoring in pilot | E13: Included (credibility score, indicative only)
A14: Creator discovery | B14: Brand-suitability scoring | C14: Not covered in feedback file | D14: Not available yet (build-vs-partner decision) | E14: Not shown in screenshots
A15: CAMPAIGN & OUTREACH
A16: Campaign & outreach | B16: Media plans | C16: No end-to-end workflow | D16: Unlimited | E16: –
A17: Campaign & outreach | B17: Bulk email outreach | C17: No end-to-end workflow | D17: Unlimited, sent from Dentsu's own domain | E17: –
A18: Campaign & outreach | B18: WhatsApp | C18: Not covered in feedback file | D18: AI negotiation via WhatsApp & email (beta) | E18: – (WhatsApp API charges excluded, passed through at cost)
A19: Campaign & outreach | B19: Live campaigns | C19: Campaign Management with CPE / CPM / ROI once budget is entered | D19: Unlimited | E19: 200 campaigns / year
A20: Campaign & outreach | B20: E-sign contracts | C20: Not covered in feedback file | D20: Not stated | E20: DocuSeal included
A21: Campaign & outreach | B21: AI automation | C21: Not covered in feedback file | D21: 5 AI modules: discovery, scripting, negotiation, content audit, performance (all beta) | E21: Not stated
A22: REPORTING
A23: Reporting | B23: ROI reports | C23: ROI in Campaign Management; static posts blank until Est. Impressions (Q4); shares / saves manual only | D23: Unlimited | E23: 200 / year (up to 100 links each = 20,000 links)
A24: Reporting | B24: UTM tracking | C24: Custom link tracking & promo codes | D24: Unlimited | E24: Included
A25: Reporting | B25: Export & integration | C25: Not covered in feedback file | D25: PowerPoint export manual on request; API / BI integration with limitations | E25: CSV / PDF export; no bulk API / scripted export
A26: Reporting | B26: Dashboards | C26: Not covered in feedback file | D26: Real-time auto-generated dashboard | E26: Master dashboard + grouping reports
A27: CRM & MIGRATION
A28: CRM & migration | B28: Influencer CRM | C28: Not covered in feedback file | D28: Unlimited (CSV / Excel migration) | E28: Up to 10,000 creators
A29: CRM & migration | B29: Migration support | C29: Not covered in feedback file | D29: Included, up to 24 months of history | E29: One-time at onboarding
A30: MONITORING & LISTENING
A31: Monitoring & listening | B31: Brand / profile monitoring | C31: Not covered in feedback file | D31: Profile monitoring: Unlimited | E31: Unlimited (500 active at once; 200 swaps / month)
A32: Monitoring & listening | B32: Hashtag tracking | C32: Hashtags only, no keyword / Boolean | D32: Unlimited | E32: Unlimited (100 active at once; ≥50 posts / day / platform, best-effort)
A33: Monitoring & listening | B33: Post analysis | C33: Not covered in feedback file | D33: 10,000 / month | E33: 3,000 / month (pooled)
A34: Monitoring & listening | B34: Comment analysis | C34: Sentiment score only; comment-level view declined | D34: 25,000 / month | E34: 10,000 / month (pooled)
A35: Monitoring & listening | B35: Collaboration analysis | C35: Not covered in feedback file | D35: Unlimited | E35: 2,000 posts / month
A36: Monitoring & listening | B36: Competitor watch | C36: 5 brands max, Instagram-led; more brands = custom dev | D36: Unlimited, with Share-of-Voice | E36: 100 watches / year
A37: Monitoring & listening | B37: Benchmark / category reports | C37: Not covered in feedback file | D37: Category intelligence reports | E37: 100 Market Benchmarking PDFs / year
A38: SUPPORT
A39: Support | B39: Account management | C39: Not covered in feedback file | D39: Indonesia-based team (30 people); relationship-manager model TBC | E39: Single named CSM for ID + TH
A40: Support | B40: Support hours | C40: Not covered in feedback file | D40: TBC | E40: Mon–Fri 9AM–6PM IST (stated as 'aligned to WIB' — to clarify)
A41: Support | B41: Onboarding & training | C41: Not covered in feedback file | D41: Unlimited, delivered locally | E41: Custom (minimum 2 sessions)
...

Sheet Gaps & Risks
A1: Known Gaps, Caveats & Risks
A2: Taken from each vendor's own caveats (Viral Pitch slide 35, CultureX guardrails) and Dentsu's HypeAuditor feedback.
A4: HypeAuditor | B4: Viral Pitch | C4: CultureX
A5: Base licence price not in source files (TBC) | B5: Only 1 of 6 RFP pricing options confirmed (12-month Indonesia); 5 in progress | C5: Highest price on the like-for-like option ($54,000 vs $35,988 for 12-month Indonesia)
A6: TikTok competitor analysis only as custom development: $150,000 | B6: X and Threads discovery limited today | C6: Hard caps: 200 campaigns, 200 ROI reports, 100 competitor watches per year
A7: 15–20 brand comparison and keyword / Boolean tracking need custom development (unpriced) | B7: Brand-suitability scoring not yet available | C7: Bulk email, WhatsApp and Media Plans shown as '–'
A8: Declined to expose comment-level sentiment | B8: AI modules, deeper fraud scoring and engagement-quality scoring are beta / in development | C8: Quarterly usage review lets CultureX propose a plan amendment
A9: Shares / saves manual only; Estimated Impressions for static posts not until Q4 | B9: No native PowerPoint export (manual on request) | C9: Listening is 'representative, not exhaustive'; SLA is best-effort
A10: History beyond 2 years costs $36,000 per extra year; no commitment yet on social-listening depth | B10: Listening configured per client / market, not always-on | C10: Support hours quoted in IST (India time), not WIB
A12: Open questions before decision
A13: Vendor | B13: Question
A14: HypeAuditor | B14: Base licence / renewal price; prices for 15–20 brand comparison and keyword tracking; whether the $150,000 TikTok build can be waived or absorbed; confirm Q3 / Q4 delivery
A15: Viral Pitch | B15: Pricing for the remaining 5 options (6/24 months; ID + TH), payment terms, tax treatment, SLA figures and support hours
A16: Viral Pitch | B16: Target dates for X / Threads, brand-suitability and fraud scoring; Boolean keyword tracking; saves metric
A17: CultureX | B17: Historical data depth, keyword / Boolean tracking, shares & saves, static-post metrics, X / Threads coverage
A18: CultureX | B18: Why Bulk Email, WhatsApp and Media Plans show '–'; team-login count; support hours in WIB vs IST
A19: All | B19: Live demo on the same Indonesian brand / use case so the outputs can be compared directly
